Workbook
Name Slicer_category: #N/A
Name Slicer_stock_status: #N/A
Name Slicer_supplier_name: #N/A
Name Slicer_warehouse_section: #N/A

Sheet raw_data
A1: medicine_id | B1: medicine_name | C1: generic_name | D1: category | E1: dosage_form | F1: unit_price | G1: batch_number | H1: quantity_in_stock | I1: reorder_level | J1: reorder_quantity | K1: expiry_date | L1: days_to_expiry | M1: warehouse_section | N1: supplier_name | O1: lead_time_days | P1: current_stock_value | Q1: stock_status
A2: MED004 | B2: Atorvastatin 10mg Tablets | C2: Atorvastatin | D2: Cholesterol | E2: Tablet | F2: 15 | G2: BCH30926 | H2: 0 | I2: 29 | J2: 210 | K2: 46130 | L2: 52 | M2: B3 | N2: Sun Pharma Distributors | O2: 5 | P2: 0 | Q2: Out of Stock
A3: MED015 | B3: Ciprofloxacin 500mg Tablets | C3: Ciprofloxacin | D3: Antibiotic | E3: Tablet | F3: 18 | G3: BCH24371 | H3: 405 | I3: 63 | J3: 316 | K3: 45266 | L3: -812 | M3: A2 | N3: Sun Pharma Distributors | O3: 5 | P3: 7290 | Q3: Already expired
A4: MED032 | B4: Furosemide 40mg Tablets | C4: Furosemide | D4: Diuretic | E4: Tablet | F4: 5.5 | G4: BCH62772 | H4: 409 | I4: 75 | J4: 155 | K4: 46037 | L4: -41 | M4: B1 | N4: Sun Pharma Distributors | O4: 5 | P4: 2249.5 | Q4: Already expired
A5: MED035 | B5: Iron Supplement 200mg | C5: Ferrous Sulphate | D5: Supplement | E5: Tablet | F5: 4.5 | G5: BCH95477 | H5: 496 | I5: 25 | J5: 221 | K5: 45480 | L5: -598 | M5: A3 | N5: Sun Pharma Distributors | O5: 5 | P5: 2232 | Q5: Already expired
A6: MED039 | B6: Levofloxacin 500mg Tablets | C6: Levofloxacin | D6: Antibiotic | E6: Tablet | F6: 28 | G6: BCH85914 | H6: 31 | I6: 67 | J6: 260 | K6: 46410 | L6: 332 | M6: A1 | N6: Sun Pharma Distributors | O6: 5 | P6: 868 | Q6: Low Stock
A7: MED040 | B7: Warfarin 5mg Tablets | C7: Warfarin | D7: Anticoagulant | E7: Tablet | F7: 18 | G7: BCH86569 | H7: 470 | I7: 74 | J7: 371 | K7: 46145 | L7: 67 | M7: A3 | N7: Sun Pharma Distributors | O7: 5 | P7: 8460 | Q7: Expiring Soon
A8: MED041 | B8: Multivitamin Syrup 200ml | C8: Multivitamin | D8: Vitamin | E8: Syrup | F8: 55 | G8: BCH76562 | H8: 35 | I8: 58 | J8: 134 | K8: 45192 | L8: -886 | M8: B1 | N8: Sun Pharma Distributors | O8: 5 | P8: 1925 | Q8: Low Stock
A9: MED002 | B9: Paracetamol 500mg Tablets | C9: Paracetamol | D9: Painkiller | E9: Tablet | F9: 5 | G9: BCH10464 | H9: 326 | I9: 36 | J9: 182 | K9: 45451 | L9: -627 | M9: C2 | N9: Sun Pharma Distributors | O9: 5 | P9: 1630 | Q9: Already expired
A10: MED004 | B10: Atorvastatin 10mg Tablets | C10: Atorvastatin | D10: Cholesterol | E10: Tablet | F10: 15 | G10: BCH58393 | H10: 75 | I10: 47 | J10: 165 | K10: 46253 | L10: 175 | M10: A1 | N10: Sun Pharma Distributors | O10: 5 | P10: 1125 | Q10: Healthy
A11: MED009 | B11: Amlodipine 5mg Tablets | C11: Amlodipine | D11: Antihypertensive | E11: Tablet | F11: 11 | G11: BCH71694 | H11: 418 | I11: 78 | J11: 335 | K11: 45337 | L11: -741 | M11: B3 | N11: Sun Pharma Distributors | O11: 5 | P11: 4598 | Q11: Already expired
A12: MED013 | B12: Pantoprazole 40mg Tablets | C12: Pantoprazole | D12: Antacid | E12: Tablet | F12: 10.5 | G12: BCH24208 | H12: 176 | I12: 66 | J12: 260 | K12: 46084 | L12: 6 | M12: C1 | N12: Sun Pharma Distributors | O12: 5 | P12: 1848 | Q12: Expiring Soon
A13: MED015 | B13: Ciprofloxacin 500mg Tablets | C13: Ciprofloxacin | D13: Antibiotic | E13: Tablet | F13: 18 | G13: BCH67154 | H13: 473 | I13: 71 | J13: 375 | K13: 45658 | L13: -420 | M13: B1 | N13: Sun Pharma Distributors | O13: 5 | P13: 8514 | Q13: Already expired
... A101: MED043 | B101: Antacid Suspension 200ml | C101: Magnesium Hydroxide | D101: Antacid | E101: Syrup | F101: 32 | G101: BCH29973 | H101: 242 | I101: 62 | J101: 158 | K101: 45354 | L101: -724 | M101: B1 | N101: Biocon Biologics | O101: 10 | P101: 7744 | Q101: Already expired

Sheet sales_data
A1: Sales Data
A3: sale_id | B3: medicine_id | C3: sale_date | D3: quantity_sold | E3: unit_price | F3: total_amount | G3: patient_type | H3: prescription_no | I3: pharmacist_id
A4: 1 | B4: MED050 | C4: 44821 | D4: 8 | E4: 3.5 | F4: 28 | G4: Inpatient | H4: RX721254 | I4: PH005
A5: 2 | B5: MED021 | C5: 45575 | D5: 4 | E5: 8 | F5: 32 | G5: Outpatient | I5: PH008
A6: 3 | B6: MED016 | C6: 45367 | D6: 8 | E6: 14 | F6: 112 | G6: Emergency | H6: RX497399 | I6: PH006
A7: 4 | B7: MED002 | C7: 44843 | D7: 6 | E7: 5 | F7: 30 | G7: Outpatient | H7: RX472060 | I7: PH005
A8: 5 | B8: MED022 | C8: 44403 | D8: 10 | E8: 9.5 | F8: 95 | G8: Emergency | H8: RX682789 | I8: PH001
A9: 6 | B9: MED034 | C9: 45772 | D9: 4 | E9: 8.5 | F9: 34 | G9: Outpatient | I9: PH007
A10: 7 | B10: MED032 | C10: 44968 | D10: 4 | E10: 5.5 | F10: 22 | G10: Emergency | H10: RX846420 | I10: PH008
A11: 8 | B11: MED029 | C11: 45454 | D11: 1 | E11: 85 | F11: 85 | G11: Outpatient | I11: PH007
A12: 9 | B12: MED045 | C12: 44329 | D12: 5 | E12: 10 | F12: 50 | G12: Emergency | H12: RX596249 | I12: PH009
A13: 10 | B13: MED034 | C13: 44535 | D13: 7 | E13: 8.5 | F13: 59.5 | G13: Emergency | H13: RX468900 | I13: PH008
A14: 11 | B14: MED018 | C14: 44458 | D14: 5 | E14: 35 | F14: 175 | G14: Outpatient | I14: PH004
A15: 12 | B15: MED021 | C15: 44075 | D15: 9 | E15: 8 | F15: 72 | G15: Emergency | I15: PH004
A16: 13 | B16: MED048 | C16: 44822 | D16: 5 | E16: 22 | F16: 110 | G16: Emergency | H16: RX897135 | I16: PH009
A17: 14 | B17: MED039 | C17: 44410 | D17: 2 | E17: 28 | F17: 56 | G17: Outpatient | I17: PH006
A18: 15 | B18: MED012 | C18: 44450 | D18: 1 | E18: 13 | F18: 13 | G18: Emergency | H18: RX387636 | I18: PH001
A19: 16 | B19: MED004 | C19: 44964 | D19: 5 | E19: 15 | F19: 75 | G19: Emergency | H19: RX768854 | I19: PH008
A20: 17 | B20: MED007 | C20: 45618 | D20: 1 | E20: 6.5 | F20: 6.5 | G20: Emergency | I20: PH008
A21: 18 | B21: MED029 | C21: 44528 | D21: 3 | E21: 85 | F21: 255 | G21: Outpatient | I21: PH008
A22: 19 | B22: MED008 | C22: 45514 | D22: 2 | E22: 4.5 | F22: 9 | G22: Inpatient | H22: RX705050 | I22: PH001
A23: 20 | B23: MED010 | C23: 44136 | D23: 10 | E23: 280 | F23: 2800 | G23: Inpatient | I23: PH004
A24: 21 | B24: MED008 | C24: 44973 | D24: 7 | E24: 4.5 | F24: 31.5 | G24: Emergency | H24: RX748458 | I24: PH004
A25: 22 | B25: MED050 | C25: 44901 | D25: 7 | E25: 3.5 | F25: 24.5 | G25: Inpatient | H25: RX411797 | I25: PH010
A26: 23 | B26: MED028 | C26: 44456 | D26: 10 | E26: 7 | F26: 70 | G26: Emergency | I26: PH002
A27: 24 | B27: MED049 | C27: 44256 | D27: 4 | E27: 35 | F27: 140 | G27: Inpatient | H27: RX264686 | I27: PH004
A28: 25 | B28: MED012 | C28: 44961 | D28: 2 | E28: 13 | F28: 26 | G28: Outpatient | I28: PH008
A29: 26 | B29: MED045 | C29: 45047 | D29: 8 | E29: 10 | F29: 80 | G29: Inpatient | I29: PH005
A30: 27 | B30: MED046 | C30: 44410 | D30: 8 | E30: 95 | F30: 760 | G30: Outpatient | H30: RX377405 | I30: PH010
A31: 28 | B31: MED043 | C31: 45477 | D31: 4 | E31: 32 | F31: 128 | G31: Inpatient | I31: PH004
A32: 29 | B32: MED042 | C32: 44136 | D32: 5 | E32: 38 | F32: 190 | G32: Outpatient | I32: PH003
A33: 30 | B33: MED020 | C33: 45049 | D33: 10 | E33: 20 | F33: 200 | G33: Inpatient | H33: RX591465 | I33: PH005
A34: 31 | B34: MED045 | C34: 44655 | D34: 5 | E34: 10 | F34: 50 | G34: Emergency | H34: RX559023 | I34: PH002
A35: 32 | B35: MED039 | C35: 43912 | D35: 7 | E35: 28 | F35: 196 | G35: Emergency | H35: RX362529 | I35: PH001
A36: 33 | B36: MED006 | C36: 44299 | D36: 10 | E36: 22 | F36: 220 | G36: Emergency | H36: RX901909 | I36: PH005
A37: 34 | B37: MED037 | C37: 43913 | D37: 3 | E37: 11 | F37: 33 | G37: Inpatient | H37: RX563711 | I37: PH005
A38: 35 | B38: MED012 | C38: 45029 | D38: 7 | E38: 13 | F38: 91 | G38: Emergency | H38: RX195674 | I38: PH008
A39: 36 | B39: MED023 | C39: 44667 | D39: 6 | E39: 7.5 | F39: 45 | G39: Inpatient | H39: RX999398 | I39: PH003
A40: 37 | B40: MED022 | C40: 44674 | D40: 8 | E40: 9.5 | F40: 76 | G40: Inpatient | H40: RX519904 | I40: PH009
A41: 38 | B41: MED003 | C41: 44762 | D41: 2 | E41: 8.75 | F41: 17.5 | G41: Inpatient | I41: PH002
...

Sheet ABC_Analysis
A1: ABC Analysis
A2: Classifies every medicine as A (top 70% revenue), B (next 20%), or C (bottom 10%) using cumulative percentage formulas.
A5: medicine_id | B5: Medicine name | C5: Category | D5: Total revenue | E5: Rank | F5: Running Total | G5: Grand Total | H5: Cumulative % | I5: ABC class | J5: Label | K5: Value
A6: MED010 | B6: =VLOOKUP(TRIM(A6),raw_data!$A:$Q,2,0) -> Insulin Glargine 100U/ml | C6: =VLOOKUP(TRIM(A6),raw_data!$A:$Q,4,0) -> Antidiabetic | D6: =SUMIF(raw_data!$A$2:$A$101, A6,raw_data!$P$2:$P$101) -> 125720 | E6: =RANK(D6,D$6:D$55,0) -> 1 | F6: =SUM(D$6:D6) -> 125720 | G6: =SUM(D$6:D$55) -> 591208.75 | H6: =ROUND((F6/G6)*100,2) -> 21.26 | I6: =IF(H6<=70,"A - High Value",IF(H6<=90,"B - Medium Value","C - Low Value")) -> A - High Value | J6: A - High Value | K6: =COUNTIF(I:I,"A - High Value") -> 12
A7: MED029 | B7: =VLOOKUP(TRIM(A7),raw_data!$A:$Q,2,0) -> Ceftriaxone 1g Injection | C7: =VLOOKUP(TRIM(A7),raw_data!$A:$Q,4,0) -> Antibiotic | D7: =SUMIF(raw_data!$A$2:$A$101, A7,raw_data!$P$2:$P$101) -> 64090 | E7: =RANK(D7,D$6:D$55,0) -> 2 | F7: =SUM(D$6:D7) -> 189810 | G7: =SUM(D$6:D$55) -> 591208.75 | H7: =ROUND((F7/G7)*100,2) -> 32.11 | I7: =IF(H7<=70,"A - High Value",IF(H7<=90,"B - Medium Value","C - Low Value")) -> A - High Value | J7: B - Medium Value | K7: =COUNTIF(I:I,"B - Medium Value") -> 14
A8: MED046 | B8: =VLOOKUP(TRIM(A8),raw_data!$A:$Q,2,0) -> Morphine 10mg Injection | C8: =VLOOKUP(TRIM(A8),raw_data!$A:$Q,4,0) -> Opioid Analgesic | D8: =SUMIF(raw_data!$A$2:$A$101, A8,raw_data!$P$2:$P$101) -> 39900 | E8: =RANK(D8,D$6:D$55,0) -> 3 | F8: =SUM(D$6:D8) -> 229710 | G8: =SUM(D$6:D$55) -> 591208.75 | H8: =ROUND((F8/G8)*100,2) -> 38.85 | I8: =IF(H8<=70,"A - High Value",IF(H8<=90,"B - Medium Value","C - Low Value")) -> A - High Value | J8: C - Low Value | K8: =COUNTIF(I:I,"C - Low Value") -> 24
A9: MED049 | B9: =VLOOKUP(TRIM(A9),raw_data!$A:$Q,2,0) -> Eye Drops Ciprofloxacin 0.3% | C9: =VLOOKUP(TRIM(A9),raw_data!$A:$Q,4,0) -> Antibiotic | D9: =SUMIF(raw_data!$A$2:$A$101, A9,raw_data!$P$2:$P$101) -> 33110 | E9: =RANK(D9,D$6:D$55,0) -> 4 | F9: =SUM(D$6:D9) -> 262820 | G9: =SUM(D$6:D$55) -> 591208.75 | H9: =ROUND((F9/G9)*100,2) -> 44.45 | I9: =IF(H9<=70,"A - High Value",IF(H9<=90,"B - Medium Value","C - Low Value")) -> A - High Value
A10: MED042 | B10: =VLOOKUP(TRIM(A10),raw_data!$A:$Q,2,0) -> Cough Syrup 100ml | C10: =VLOOKUP(TRIM(A10),raw_data!$A:$Q,4,0) -> Cough Suppressant | D10: =SUMIF(raw_data!$A$2:$A$101, A10,raw_data!$P$2:$P$101) -> 29716 | E10: =RANK(D10,D$6:D$55,0) -> 5 | F10: =SUM(D$6:D10) -> 292536 | G10: =SUM(D$6:D$55) -> 591208.75 | H10: =ROUND((F10/G10)*100,2) -> 49.48 | I10: =IF(H10<=70,"A - High Value",IF(H10<=90,"B - Medium Value","C - Low Value")) -> A - High Value
A11: MED047 | B11: =VLOOKUP(TRIM(A11),raw_data!$A:$Q,2,0) -> Hydrocortisone Cream 1% | C11: =VLOOKUP(TRIM(A11),raw_data!$A:$Q,4,0) -> Corticosteroid | D11: =SUMIF(raw_data!$A$2:$A$101, A11,raw_data!$P$2:$P$101) -> 17668 | E11: =RANK(D11,D$6:D$55,0) -> 6 | F11: =SUM(D$6:D11) -> 310204 | G11: =SUM(D$6:D$55) -> 591208.75 | H11: =ROUND((F11/G11)*100,2) -> 52.47 | I11: =IF(H11<=70,"A - High Value",IF(H11<=90,"B - Medium Value","C - Low Value")) -> A - High Value
A12: MED011 | B12: =VLOOKUP(TRIM(A12),raw_data!$A:$Q,2,0) -> Salbutamol Inhaler 100mcg | C12: =VLOOKUP(TRIM(A12),raw_data!$A:$Q,4,0) -> Bronchodilator | D12: =SUMIF(raw_data!$A$2:$A$101, A12,raw_data!$P$2:$P$101) -> 17280 | E12: =RANK(D12,D$6:D$55,0) -> 7 | F12: =SUM(D$6:D12) -> 327484 | G12: =SUM(D$6:D$55) -> 591208.75 | H12: =ROUND((F12/G12)*100,2) -> 55.39 | I12: =IF(H12<=70,"A - High Value",IF(H12<=90,"B - Medium Value","C - Low Value")) -> A - High Value
A13: MED043 | B13: =VLOOKUP(TRIM(A13),raw_data!$A:$Q,2,0) -> Antacid Suspension 200ml | C13: =VLOOKUP(TRIM(A13),raw_data!$A:$Q,4,0) -> Antacid | D13: =SUMIF(raw_data!$A$2:$A$101, A13,raw_data!$P$2:$P$101) -> 16288 | E13: =RANK(D13,D$6:D$55,0) -> 8 | F13: =SUM(D$6:D13) -> 343772 | G13: =SUM(D$6:D$55) -> 591208.75 | H13: =ROUND((F13/G13)*100,2) -> 58.15 | I13: =IF(H13<=70,"A - High Value",IF(H13<=90,"B - Medium Value","C - Low Value")) -> A - High Value
A14: MED006 | B14: =VLOOKUP(TRIM(A14),raw_data!$A:$Q,2,0) -> Azithromycin 250mg Tablets | C14: =VLOOKUP(TRIM(A14),raw_data!$A:$Q,4,0) -> Antibiotic | D14: =SUMIF(raw_data!$A$2:$A$101, A14,raw_data!$P$2:$P$101) -> 16148 | E14: =RANK(D14,D$6:D$55,0) -> 9 | F14: =SUM(D$6:D14) -> 359920 | G14: =SUM(D$6:D$55) -> 591208.75 | H14: =ROUND((F14/G14)*100,2) -> 60.88 | I14: =IF(H14<=70,"A - High Value",IF(H14<=90,"B - Medium Value","C - Low Value")) -> A - High Value
A15: MED015 | B15: =VLOOKUP(TRIM(A15),raw_data!$A:$Q,2,0) -> Ciprofloxacin 500mg Tablets | C15: =VLOOKUP(TRIM(A15),raw_data!$A:$Q,4,0) -> Antibiotic | D15: =SUMIF(raw_data!$A$2:$A$101, A15,raw_data!$P$2:$P$101) -> 15804 | E15: =RANK(D15,D$6:D$55,0) -> 10 | F15: =SUM(D$6:D15) -> 375724 | G15: =SUM(D$6:D$55) -> 591208.75 | H15: =ROUND((F15/G15)*100,2) -> 63.55 | I15: =IF(H15<=70,"A - High Value",IF(H15<=90,"B - Medium Value","C - Low Value")) -> A - High Value
A16: MED017 | B16: =VLOOKUP(TRIM(A16),raw_data!$A:$Q,2,0) -> Fluconazole 150mg Capsules | C16: =VLOOKUP(TRIM(A16),raw_data!$A:$Q,4,0) -> Antifungal | D16: =SUMIF(raw_data!$A$2:$A$101, A16,raw_data!$P$2:$P$101) -> 14000 | E16: =RANK(D16,D$6:D$55,0) -> 11 | F16: =SUM(D$6:D16) -> 389724 | G16: =SUM(D$6:D$55) -> 591208.75 | H16: =ROUND((F16/G16)*100,2) -> 65.92 | I16: =IF(H16<=70,"A - High Value",IF(H16<=90,"B - Medium Value","C - Low Value")) -> A - High Value
A17: MED026 | B17: =VLOOKUP(TRIM(A17),raw_data!$A:$Q,2,0) -> Tramadol 50mg Capsules | C17: =VLOOKUP(TRIM(A17),raw_data!$A:$Q,4,0) -> Opioid Analgesic | D17: =SUMIF(raw_data!$A$2:$A$101, A17,raw_data!$P$2:$P$101) -> 12300 | E17: =RANK(D17,D$6:D$55,0) -> 12 | F17: =SUM(D$6:D17) -> 402024 | G17: =SUM(D$6:D$55) -> 591208.75 | H17: =ROUND((F17/G17)*100,2) -> 68 | I17: =IF(H17<=70,"A - High Value",IF(H17<=90,"B - Medium Value","C - Low Value")) -> A - High Value
A18: MED018 | B18: =VLOOKUP(TRIM(A18),raw_data!$A:$Q,2,0) -> Dexamethasone 4mg Injection | C18: =VLOOKUP(TRIM(A18),raw_data!$A:$Q,4,0) -> Corticosteroid | D18: =SUMIF(raw_data!$A$2:$A$101, A18,raw_data!$P$2:$P$101) -> 12145 | E18: =RANK(D18,D$6:D$55,0) -> 13 | F18: =SUM(D$6:D18) -> 414169 | G18: =SUM(D$6:D$55) -> 591208.75 | H18: =ROUND((F18/G18)*100,2) -> 70.05 | I18: =IF(H18<=70,"A - High Value",IF(H18<=90,"B - Medium Value","C - Low Value")) -> B - Medium Value
A19: MED027 | B19: =VLOOKUP(TRIM(A19),raw_data!$A:$Q,2,0) -> Ondansetron 4mg Tablets | C19: =VLOOKUP(TRIM(A19),raw_data!$A:$Q,4,0) -> Antiemetic | D19: =SUMIF(raw_data!$A$2:$A$101, A19,raw_data!$P$2:$P$101) -> 11248 | E19: =RANK(D19,D$6:D$55,0) -> 14 | F19: =SUM(D$6:D19) -> 425417 | G19: =SUM(D$6:D$55) -> 591208.75 | H19: =ROUND((F19/G19)*100,2) -> 71.96 | I19: =IF(H19<=70,"A - High Value",IF(H19<=90,"B - Medium Value","C - Low Value")) -> B - Medium Value
A20: MED040 | B20: =VLOOKUP(TRIM(A20),raw_data!$A:$Q,2,0) -> Warfarin 5mg Tablets | C20: =VLOOKUP(TRIM(A20),raw_data!$A:$Q,4,0) -> Anticoagulant | D20: =SUMIF(raw_data!$A$2:$A$101, A20,raw_data!$P$2:$P$101) -> 11016 | E20: =RANK(D20,D$6:D$55,0) -> 15 | F20: =SUM(D$6:D20) -> 436433 | G20: =SUM(D$6:D$55) -> 591208.75 | H20: =ROUND((F20/G20)*100,2) -> 73.82 | I20: =IF(H20<=70,"A - High Value",IF(H20<=90,"B - Medium Value","C - Low Value")) -> B - Medium Value
... A55: MED003 | B55: =VLOOKUP(TRIM(A55),raw_data!$A:$Q,2,0) -> Metformin 500mg Tablets | C55: =VLOOKUP(TRIM(A55),raw_data!$A:$Q,4,0) -> Antidiabetic | D55: =SUMIF(raw_data!$A$2:$A$101, A55,raw_data!$P$2:$P$101) -> 498.75 | E55: =RANK(D55,D$6:D$55,0) -> 50 | F55: =SUM(D$6:D55) -> 591208.75 | G55: =SUM(D$6:D$55) -> 591208.75 | H55: =ROUND((F55/G55)*100,2) -> 100 | I55: =IF(H55<=70,"A - High Value",IF(H55<=90,"B - Medium Value","C - Low Value")) -> C - Low Value

Sheet EOQ_calculator
A1: Economic Order Quantity (EOQ) Calculation
A2: Economic Order Quantity (EOQ) is the ideal quantity to order each time to minimise total inventory cost — balancing the cost of ordering too frequently vs holding too much stock.
A4: ASSUMPTIONS | B4: Ordering Cost Per Order | C4: 500
B5: Holding Cost % of Unit Price | C5: 0.25
B6: Analysis Date | C6: =TODAY() -> 46080
A8: Medicine ID | B8: Medicine Name | C8: Category | D8: Unit Price | E8: Annual Demand (units) | F8: Ordering Cost (Rs) | G8: Holding Cost Per Unit (Rs) | H8: EOQ (Units) | I8: Current reorder Quantity | J8: Reorder Level | K8: Difference ( EOQ vs Current)
A9: MED004 | B9: =VLOOKUP(TRIM(A9),raw_data!$A:$Q,2,0) -> Atorvastatin 10mg Tablets | C9: =VLOOKUP(TRIM(A9),raw_data!$A:$Q,4,0) -> Cholesterol | D9: =VLOOKUP(TRIM(A9),raw_data!$A:$Q,6,0) -> 15 | E9: =SUMIF(sales_data!B:B,A9,sales_data!D:D) -> 44 | F9: =$C$4 -> 500 | G9: =ROUND(D9*$C$5,2) -> 3.75 | H9: =IFERROR(ROUND(SQRT((E9*F9)/G9),0),0) -> 77 | I9: =IFERROR(SUMIF(raw_data!A:A,A9,raw_data!J:J)/ COUNTIF(raw_data!A:A,A9),0) -> 187.5 | J9: =IFERROR(SUMIF(raw_data!$A:$A,A9,raw_data!$I:$I)/ COUNTIF(raw_data!$A:$A,A9),0) -> 38 | K9: =H9-I9 -> -110.5
A10: MED015 | B10: =VLOOKUP(TRIM(A10),raw_data!$A:$Q,2,0) -> Ciprofloxacin 500mg Tablets | C10: =VLOOKUP(TRIM(A10),raw_data!$A:$Q,4,0) -> Antibiotic | D10: =VLOOKUP(TRIM(A10),raw_data!$A:$Q,6,0) -> 18 | E10: =SUMIF(sales_data!B:B,A10,sales_data!D:D) -> 50 | F10: =$C$4 -> 500 | G10: =ROUND(D10*$C$5,2) -> 4.5 | H10: =IFERROR(ROUND(SQRT((E10*F10)/G10),0),0) -> 75 | I10: =IFERROR(SUMIF(raw_data!A:A,A10,raw_data!J:J)/ COUNTIF(raw_data!A:A,A10),0) -> 345.5 | J10: =IFERROR(SUMIF(raw_data!$A:$A,A10,raw_data!$I:$I)/ COUNTIF(raw_data!$A:$A,A10),0) -> 67 | K10: =H10-I10 -> -270.5
A11: MED032 | B11: =VLOOKUP(TRIM(A11),raw_data!$A:$Q,2,0) -> Furosemide 40mg Tablets | C11: =VLOOKUP(TRIM(A11),raw_data!$A:$Q,4,0) -> Diuretic | D11: =VLOOKUP(TRIM(A11),raw_data!$A:$Q,6,0) -> 5.5 | E11: =SUMIF(sales_data!B:B,A11,sales_data!D:D) -> 72 | F11: =$C$4 -> 500 | G11: =ROUND(D11*$C$5,2) -> 1.38 | H11: =IFERROR(ROUND(SQRT((E11*F11)/G11),0),0) -> 162 | I11: =IFERROR(SUMIF(raw_data!A:A,A11,raw_data!J:J)/ COUNTIF(raw_data!A:A,A11),0) -> 231.5 | J11: =IFERROR(SUMIF(raw_data!$A:$A,A11,raw_data!$I:$I)/ COUNTIF(raw_data!$A:$A,A11),0) -> 60.5 | K11: =H11-I11 -> -69.5
A12: MED035 | B12: =VLOOKUP(TRIM(A12),raw_data!$A:$Q,2,0) -> Iron Supplement 200mg | C12: =VLOOKUP(TRIM(A12),raw_data!$A:$Q,4,0) -> Supplement | D12: =VLOOKUP(TRIM(A12),raw_data!$A:$Q,6,0) -> 4.5 | E12: =SUMIF(sales_data!B:B,A12,sales_data!D:D) -> 49 | F12: =$C$4 -> 500 | G12: =ROUND(D12*$C$5,2) -> 1.13 | H12: =IFERROR(ROUND(SQRT((E12*F12)/G12),0),0) -> 147 | I12: =IFERROR(SUMIF(raw_data!A:A,A12,raw_data!J:J)/ COUNTIF(raw_data!A:A,A12),0) -> 300 | J12: =IFERROR(SUMIF(raw_data!$A:$A,A12,raw_data!$I:$I)/ COUNTIF(raw_data!$A:$A,A12),0) -> 46 | K12: =H12-I12 -> -153
A13: MED039 | B13: =VLOOKUP(TRIM(A13),raw_data!$A:$Q,2,0) -> Levofloxacin 500mg Tablets | C13: =VLOOKUP(TRIM(A13),raw_data!$A:$Q,4,0) -> Antibiotic | D13: =VLOOKUP(TRIM(A13),raw_data!$A:$Q,6,0) -> 28 | E13: =SUMIF(sales_data!B:B,A13,sales_data!D:D) -> 70 | F13: =$C$4 -> 500 | G13: =ROUND(D13*$C$5,2) -> 7 | H13: =IFERROR(ROUND(SQRT((E13*F13)/G13),0),0) -> 71 | I13: =IFERROR(SUMIF(raw_data!A:A,A13,raw_data!J:J)/ COUNTIF(raw_data!A:A,A13),0) -> 234 | J13: =IFERROR(SUMIF(raw_data!$A:$A,A13,raw_data!$I:$I)/ COUNTIF(raw_data!$A:$A,A13),0) -> 53.5 | K13: =H13-I13 -> -163
A14: MED040 | B14: =VLOOKUP(TRIM(A14),raw_data!$A:$Q,2,0) -> Warfarin 5mg Tablets | C14: =VLOOKUP(TRIM(A14),raw_data!$A:$Q,4,0) -> Anticoagulant | D14: =VLOOKUP(TRIM(A14),raw_data!$A:$Q,6,0) -> 18 | E14: =SUMIF(sales_data!B:B,A14,sales_data!D:D) -> 24 | F14: =$C$4 -> 500 | G14: =ROUND(D14*$C$5,2) -> 4.5 | H14: =IFERROR(ROUND(SQRT((E14*F14)/G14),0),0) -> 52 | I14: =IFERROR(SUMIF(raw_data!A:A,A14,raw_data!J:J)/ COUNTIF(raw_data!A:A,A14),0) -> 343 | J14: =IFERROR(SUMIF(raw_data!$A:$A,A14,raw_data!$I:$I)/ COUNTIF(raw_data!$A:$A,A14),0) -> 71 | K14: =H14-I14 -> -291
A15: MED041 | B15: =VLOOKUP(TRIM(A15),raw_data!$A:$Q,2,0) -> Multivitamin Syrup 200ml | C15: =VLOOKUP(TRIM(A15),raw_data!$A:$Q,4,0) -> Vitamin | D15: =VLOOKUP(TRIM(A15),raw_data!$A:$Q,6,0) -> 55 | E15: =SUMIF(sales_data!B:B,A15,sales_data!D:D) -> 81 | F15: =$C$4 -> 500 | G15: =ROUND(D15*$C$5,2) -> 13.75 | H15: =IFERROR(ROUND(SQRT((E15*F15)/G15),0),0) -> 54 | I15: =IFERROR(SUMIF(raw_data!A:A,A15,raw_data!J:J)/ COUNTIF(raw_data!A:A,A15),0) -> 206.5 | J15: =IFERROR(SUMIF(raw_data!$A:$A,A15,raw_data!$I:$I)/ COUNTIF(raw_data!$A:$A,A15),0) -> 69 | K15: =H15-I15 -> -152.5
A16: MED002 | B16: =VLOOKUP(TRIM(A16),raw_data!$A:$Q,2,0) -> Paracetamol 500mg Tablets | C16: =VLOOKUP(TRIM(A16),raw_data!$A:$Q,4,0) -> Painkiller | D16: =VLOOKUP(TRIM(A16),raw_data!$A:$Q,6,0) -> 5 | E16: =SUMIF(sales_data!B:B,A16,sales_data!D:D) -> 42 | F16: =$C$4 -> 500 | G16: =ROUND(D16*$C$5,2) -> 1.25 | H16: =IFERROR(ROUND(SQRT((E16*F16)/G16),0),0) -> 130 | I16: =IFERROR(SUMIF(raw_data!A:A,A16,raw_data!J:J)/ COUNTIF(raw_data!A:A,A16),0) -> 200.5 | J16: =IFERROR(SUMIF(raw_data!$A:$A,A16,raw_data!$I:$I)/ COUNTIF(raw_data!$A:$A,A16),0) -> 34.5 | K16: =H16-I16 -> -70.5
A17: MED009 | B17: =VLOOKUP(TRIM(A17),raw_data!$A:$Q,2,0) -> Amlodipine 5mg Tablets | C17: =VLOOKUP(TRIM(A17),raw_data!$A:$Q,4,0) -> Antihypertensive | D17: =VLOOKUP(TRIM(A17),raw_data!$A:$Q,6,0) -> 11 | E17: =SUMIF(sales_data!B:B,A17,sales_data!D:D) -> 59 | F17: =$C$4 -> 500 | G17: =ROUND(D17*$C$5,2) -> 2.75 | H17: =IFERROR(ROUND(SQRT((E17*F17)/G17),0),0) -> 104 | I17: =IFERROR(SUMIF(raw_data!A:A,A17,raw_data!J:J)/ COUNTIF(raw_data!A:A,A17),0) -> 280 | J17: =IFERROR(SUMIF(raw_data!$A:$A,A17,raw_data!$I:$I)/ COUNTIF(raw_data!$A:$A,A17),0) -> 72 | K17: =H17-I17 -> -176
A18: MED013 | B18: =VLOOKUP(TRIM(A18),raw_data!$A:$Q,2,0) -> Pantoprazole 40mg Tablets | C18: =VLOOKUP(TRIM(A18),raw_data!$A:$Q,4,0) -> Antacid | D18: =VLOOKUP(TRIM(A18),raw_data!$A:$Q,6,0) -> 10.5 | E18: =SUMIF(sales_data!B:B,A18,sales_data!D:D) -> 46 | F18: =$C$4 -> 500 | G18: =ROUND(D18*$C$5,2) -> 2.63 | H18: =IFERROR(ROUND(SQRT((E18*F18)/G18),0),0) -> 94 | I18: =IFERROR(SUMIF(raw_data!A:A,A18,raw_data!J:J)/ COUNTIF(raw_data!A:A,A18),0) -> 329.5 | J18: =IFERROR(SUMIF(raw_data!$A:$A,A18,raw_data!$I:$I)/ COUNTIF(raw_data!$A:$A,A18),0) -> 51 | K18: =H18-I18 -> -235.5
A19: MED001 | B19: =VLOOKUP(TRIM(A19),raw_data!$A:$Q,2,0) -> Amoxicillin 500mg Capsules | C19: =VLOOKUP(TRIM(A19),raw_data!$A:$Q,4,0) -> Antibiotic | D19: =VLOOKUP(TRIM(A19),raw_data!$A:$Q,6,0) -> 12.5 | E19: =SUMIF(sales_data!B:B,A19,sales_data!D:D) -> 35 | F19: =$C$4 -> 500 | G19: =ROUND(D19*$C$5,2) -> 3.13 | H19: =IFERROR(ROUND(SQRT((E19*F19)/G19),0),0) -> 75 | I19: =IFERROR(SUMIF(raw_data!A:A,A19,raw_data!J:J)/ COUNTIF(raw_data!A:A,A19),0) -> 234 | J19: =IFERROR(SUMIF(raw_data!$A:$A,A19,raw_data!$I:$I)/ COUNTIF(raw_data!$A:$A,A19),0) -> 44 | K19: =H19-I19 -> -159
A20: MED005 | B20: =VLOOKUP(TRIM(A20),raw_data!$A:$Q,2,0) -> Omeprazole 20mg Capsules | C20: =VLOOKUP(TRIM(A20),raw_data!$A:$Q,4,0) -> Antacid | D20: =VLOOKUP(TRIM(A20),raw_data!$A:$Q,6,0) -> 9 | E20: =SUMIF(sales_data!B:B,A20,sales_data!D:D) -> 41 | F20: =$C$4 -> 500 | G20: =ROUND(D20*$C$5,2) -> 2.25 | H20: =IFERROR(ROUND(SQRT((E20*F20)/G20),0),0) -> 95 | I20: =IFERROR(SUMIF(raw_data!A:A,A20,raw_data!J:J)/ COUNTIF(raw_data!A:A,A20),0) -> 221 | J20: =IFERROR(SUMIF(raw_data!$A:$A,A20,raw_data!$I:$I)/ COUNTIF(raw_data!$A:$A,A20),0) -> 42 | K20: =H20-I20 -> -126
... A58: MED014 | B58: =VLOOKUP(TRIM(A58),raw_data!$A:$Q,2,0) -> Vitamin D3 1000IU Tablets | C58: =VLOOKUP(TRIM(A58),raw_data!$A:$Q,4,0) -> Vitamin | D58: =VLOOKUP(TRIM(A58),raw_data!$A:$Q,6,0) -> 7 | E58: =SUMIF(sales_data!B:B,A58,sales_data!D:D) -> 29 | F58: =$C$4 -> 500 | G58: =ROUND(D58*$C$5,2) -> 1.75 | H58: =IFERROR(ROUND(SQRT((E58*F58)/G58),0),0) -> 91 | I58: =IFERROR(SUMIF(raw_data!A:A,A58,raw_data!J:J)/ COUNTIF(raw_data!A:A,A58),0) -> 274.5 | J58: =IFERROR(SUMIF(raw_data!$A:$A,A58,raw_data!$I:$I)/ COUNTIF(raw_data!$A:$A,A58),0) -> 54 | K58: =H58-I58 -> -183.5

Sheet KPI_Summary
A1: KPI Name | B1: Value | C1: Description
A2: Total Medicines | B2: {=SUMPRODUCT(1/COUNTIF(raw_data!A2:A101,raw_data!A2:A101))} -> 50 | C2: Unique Medicines
A4: Total Stock Value | B4: =SUMPRODUCT(raw_data!H2:H101,raw_data!F2:F101) -> 591208.75 | C4: Current value of all stocks
A6: Out Of Stock Items | B6: =COUNTIF(tbl_inventory[quantity_in_stock], 0) -> 5 | C6: Batches with zero Quantity
A8: Low Stock Items | B8: {=SUMPRODUCT((raw_data!H2:H101>0)*(raw_data!H2:H101<=raw_data!I2:I101))} -> 12 | C8: Below reorder level threshold
A10: Expiring in 90 Days | B10: =COUNTIF(raw_data!Q2:Q101, "Expiring Soon") -> 9 | C10: Expiring between today - 90 days
A12: Already Expired | B12: =COUNTIF(raw_data!Q2:Q101, "Already Expired") -> 62 | C12: Expiry date already passed
A14: Total Suppliers | B14: {=SUMPRODUCT(1/COUNTIF(raw_data!N2:N101,raw_data!N2:N101))} -> 10 | C14: Unique active suppliers
A16: Avg Lead Time (Days) | B16: =AVERAGEIF(raw_data!O2:O101, ">0") -> 5.63 | C16: Averge supplier delievery time

Sheet pivot_tables
B1: Stock Status Summary | G1: Stock Value By Category | L1: Expiry Analysis By Warehouse Section
B3: Stock Status | C3: Count | D3: Total_units | E3: Stock Value (₹) | G3: Category | H3: Total Stock value | I3: Batch Count | J3: Avg Unit Price | L3: Warehouse | M3: Status
B4: Expiring Soon | C4: 9 | D4: 2017 | E4: 44335.5 | G4: Antacid | H4: 39057.5 | I4: 10 | J4: 13.7 | L4: Section | M4: Expiring Soon | N4: Healthy | O4: Low Stock | P4: Out of Stock | Q4: Already expired | R4: Grand Total
B5: Healthy | C5: 12 | D5: 3137 | E5: 43462.5 | G5: Antibiotic | H5: 147526.5 | I5: 16 | J5: 28.375 | L5: A1 | M5: 1 | N5: 2 | O5: 2 | P5: 1 | Q5: 2 | R5: 8
B6: Low Stock | C6: 12 | D6: 449 | E6: 14048.5 | G6: Anticoagulant | H6: 11016 | I6: 2 | J6: 18 | L6: A2 | O6: 2 | Q6: 8 | R6: 10
B7: Out of Stock | C7: 5 | D7: 0 | E7: 0 | G7: Anticonvulsant | H7: 7930 | I7: 2 | J7: 10 | L7: A3 | M7: 1 | N7: 1 | O7: 1 | Q7: 8 | R7: 11
B8: Already expired | C8: 62 | D8: 19379 | E8: 489362.25 | G8: Antidepressant | H8: 10528 | I8: 4 | J8: 15.75 | L8: B1 | M8: 3 | N8: 4 | O8: 2 | Q8: 11 | R8: 20
B9: Grand Total | C9: 100 | D9: 24982 | E9: 591208.75 | G9: Antidiabetic | H9: 127996.75 | I9: 6 | J9: 98.583333 | L9: B2 | M9: 1 | N9: 1 | O9: 3 | P9: 1 | Q9: 9 | R9: 15
G10: Antiemetic | H10: 11248 | I10: 2 | J10: 16 | L10: B3 | N10: 1 | O10: 1 | P10: 1 | Q10: 4 | R10: 7
G11: Antifungal | H11: 22272 | I11: 4 | J11: 23.5 | L11: C1 | M11: 2 | N11: 1 | Q11: 6 | R11: 9
G12: Antihistamine | H12: 1462.5 | I12: 2 | J12: 4.5 | L12: C2 | N12: 1 | Q12: 8 | R12: 9
G13: Antihypertensive | H13: 24310 | I13: 6 | J13: 12.666667 | L13: Cold-Storage | M13: 1 | N13: 1 | O13: 1 | P13: 2 | Q13: 6 | R13: 11
G14: Antiplatelet | H14: 11568 | I14: 4 | J14: 12 | L14: Grand Total | M14: 9 | N14: 12 | O14: 12 | P14: 5 | Q14: 62 | R14: 100
G15: Anxiolytic | H15: 2112 | I15: 2 | J15: 12
G16: Bronchodilator | H16: 17280 | I16: 2 | J16: 45 | L16: Category vs Stock Status
G17: Cardiac Glycoside | H17: 1368 | I17: 2 | J17: 9
G18: Cholesterol | H18: 1125 | I18: 2 | J18: 15 | L18: Medicines | M18: Status
G19: Corticosteroid | H19: 36517.5 | I19: 6 | J19: 24.833333 | L19: Category | M19: Expiring Soon | N19: Healthy | O19: Low Stock | P19: Out of Stock | Q19: Already expired | R19: Grand Total
G20: Cough Suppressant | H20: 29716 | I20: 2 | J20: 38 | L20: Antacid | M20: 1 | N20: 2 | P20: 1 | Q20: 6 | R20: 10
G21: Diuretic | H21: 2425.5 | I21: 2 | J21: 5.5 | L21: Antibiotic | M21: 1 | N21: 1 | O21: 2 | P21: 1 | Q21: 11 | R21: 16
G22: Electrolyte | H22: 3013.5 | I22: 2 | J22: 3.5 | L22: Anticoagulant | M22: 1 | N22: 1 | R22: 2
G23: NSAID | H23: 8351 | I23: 4 | J23: 7.5 | L23: Anticonvulsant | Q23: 2 | R23: 2
G24: Opioid Analgesic | H24: 52200 | I24: 4 | J24: 62.5 | L24: Antidepressant | M24: 1 | O24: 1 | Q24: 2 | R24: 4
G25: Painkiller | H25: 1630 | I25: 2 | J25: 5 | L25: Antidiabetic | N25: 1 | O25: 1 | P25: 1 | Q25: 3 | R25: 6
G26: Supplement | H26: 7954.5 | I26: 4 | J26: 5.5 | L26: Antiemetic | Q26: 2 | R26: 2
G27: Vitamin | H27: 12600.5 | I27: 8 | J27: 18.375 | L27: Antifungal | M27: 1 | O27: 1 | Q27: 2 | R27: 4
G28: Grand Total | H28: 591208.75 | I28: 100 | J28: 24.245 | L28: Antihistamine | M28: 1 | Q28: 1 | R28: 2
L29: Antihypertensive | M29: 1 | Q29: 5 | R29: 6
L30: Antiplatelet | N30: 1 | Q30: 3 | R30: 4
B31: Supplier Performance Summary | L31: Anxiolytic | Q31: 2 | R31: 2
L32: Bronchodilator | M32: 2 | R32: 2
B33: Supplier Name | C33: Batch Count | D33: Total Stock Value | E33: Average Lead Days | L33: Cardiac Glycoside | Q33: 2 | R33: 2
B34: Abbott HealthCare | C34: 7 | D34: 31376.5 | E34: 7 | L34: Cholesterol | N34: 1 | P34: 1 | R34: 2
B35: Alkem Laboratories | C35: 9 | D35: 82759.5 | E35: 6 | L35: Corticosteroid | N35: 1 | O35: 1 | Q35: 4 | R35: 6
B36: Biocon Biologics | C36: 11 | D36: 37507 | E36: 10 | L36: Cough Suppressant | Q36: 2 | R36: 2
B37: Cipla Medical Supplies | C37: 14 | D37: 70240.5 | E37: 4 | L37: Diuretic | O37: 1 | Q37: 1 | R37: 2
B38: Dr. Reddy's Logistics | C38: 6 | D38: 57156.5 | E38: 6 | L38: Electrolyte | N38: 1 | Q38: 1 | R38: 2
B39: Lupin Pharmaceuticals | C39: 6 | D39: 19815 | E39: 5 | L39: NSAID | N39: 1 | O39: 1 | Q39: 2 | R39: 4
B40: Mankind Pharma | C40: 16 | D40: 99716.5 | E40: 3 | L40: Opioid Analgesic | N40: 1 | O40: 1 | Q40: 2 | R40: 4
B41: Pfizer India Ltd | C41: 11 | D41: 129708.5 | E41: 8 | L41: Painkiller | P41: 1 | Q41: 1 | R41: 2
...
